Workbook

Sheet Уроки
A1: User ID | B1: ID Class | C1: Class Start Date Time | D1: Class End Date Time | E1: Class Removed Date Time | F1: ID Teacher | G1: Class Status | H1: Class Status Date Time | I1: Class Type | J1: Class Duration
A2: 325348 | B2: 3036485 | C2: 42465.444 | D2: 42465.427 | F2: 47743 | G2: success | H2: 42465.555 | I2: regular | J2: -24.683333
A3: 250209585 | B3: 3042917 | C3: 42469.608 | D3: 42469.619 | F3: 51564 | G3: success | H3: 42469.625 | I3: regular | J3: 15.433333
A4: 518406438 | B4: 3074966 | C4: 42491.763 | D4: 42491.825 | F4: 26896 | G4: failed_by_student | H4: 42491.514 | I4: regular | J4: 89.3
A5: 666791637 | B5: 3103245 | C5: 42511.422 | D5: 42511.483 | F5: 51450 | G5: canceled_by_student | H5: 42512.234 | I5: regular | J5: 88.7
A6: 310771064 | B6: 3123907 | C6: 42525.455 | D6: 42525.454 | F6: 19513 | G6: success | H6: 42525.478 | I6: regular | J6: -1.05
A7: 820726831 | B7: 3137396 | C7: 42534.825 | D7: 42534.837 | F7: 45226 | G7: success | H7: 42535.341 | I7: regular | J7: 16.283333
A8: 87910119 | B8: 3142195 | C8: 42537.296 | D8: 42537.36 | F8: 46409 | G8: canceled_by_student | H8: 42537.587 | I8: regular | J8: 90.983333
A9: 557318231 | B9: 3163558 | C9: 42551.623 | D9: 42551.612 | F9: 16064 | G9: success | H9: 42551.796 | I9: regular | J9: -16.1
A10: 378031781 | B10: 3165081 | C10: 42552.925 | D10: 42552.95 | E10: 42552.671 | F10: 54349 | I10: regular | J10: 36.916667
A11: 819834854 | B11: 3179696 | C11: 42562.914 | D11: 42562.938 | F11: 62525 | G11: canceled_by_teacher | H11: 42562.979 | I11: regular | J11: 34.55
A12: 53930100 | B12: 3190831 | C12: 42570.739 | D12: 42570.757 | F12: 46401 | G12: success | H12: 42571.807 | I12: regular | J12: 27.05
A13: 577136653 | B13: 3393876 | C13: 42706.742 | D13: 42706.765 | F13: 73877 | G13: canceled_by_student | H13: 42707.632 | I13: single | J13: 33.466667
A14: 820269817 | B14: 3491015 | C14: 42733.853 | D14: 42733.831 | F14: 129840 | G14: failed_by_student | H14: 42733.931 | I14: single | J14: -31.833333
A15: 812848522 | B15: 3517332 | C15: 42748.424 | D15: 42748.463 | F15: 22703 | G15: canceled_by_student | H15: 42748.647 | I15: single | J15: 56.6
A16: 702993006 | B16: 3702595 | C16: 42823.712 | D16: 42823.786 | F16: 62526 | G16: success | H16: 42823.829 | I16: single | J16: 107.06667
A17: 275505680 | B17: 4493327 | C17: 43015.955 | D17: 43015.972 | F17: 26745 | G17: success | H17: 43016.42 | I17: single | J17: 23.716667
A18: 265631576 | B18: 3017789 | C18: 42452.562 | D18: 42452.577 | F18: 51907 | G18: canceled_by_teacher | H18: 42452.584 | I18: single | J18: 22.4
A19: 312890749 | B19: 3051957 | C19: 42478.436 | D19: 42478.457 | F19: 52940 | G19: success | H19: 42478.425 | I19: single | J19: 31.283333
A20: 812848522 | B20: 3459655 | C20: 42723.499 | D20: 42723.504 | F20: 22703 | G20: success | H20: 42723.543 | I20: single | J20: 7.2333333
A21: 825271993 | B21: 3481219 | C21: 42731.801 | D21: 42731.854 | F21: 37836 | G21: success | H21: 42731.832 | I21: single | J21: 75.516667
A22: 735566020 | B22: 3641656 | C22: 42824.847 | D22: 42824.922 | E22: 42810.555 | F22: 52344 | I22: single | J22: 108.6
A23: 459374225 | B23: 3744356 | C23: 42829.91 | D23: 42829.922 | F23: 74354 | G23: success | H23: 42829.957 | I23: single | J23: 17.45
A24: 750711381 | B24: 3770985 | C24: 42836.586 | D24: 42836.605 | F24: 155465 | G24: failed_by_student | H24: 42836.644 | I24: single | J24: 26.95
A25: 354074093 | B25: 4183165 | C25: 42944.828 | D25: 42944.821 | F25: 44903 | G25: success | H25: 42944.854 | I25: single | J25: -8.7333333
A26: 312890749 | B26: 4234049 | C26: 42958.425 | D26: 42958.457 | F26: 52940 | G26: success | H26: 42958.447 | I26: single | J26: 45.183333
A27: 363117914 | B27: 4240904 | C27: 42958.835 | D27: 42958.872 | F27: 121144 | G27: success | H27: 42958.921 | I27: single | J27: 54
A28: 460717125 | B28: 4279632 | C28: 42967.474 | D28: 42967.466 | F28: 138716 | G28: canceled_by_teacher | H28: 42968.441 | I28: single | J28: -10.7
A29: 646897024 | B29: 4394006 | C29: 42994.387 | D29: 42994.463 | E29: 42995.859 | F29: 15605 | G29: moved | H29: 42995.916 | I29: single | J29: 110.01667
A30: 601916433 | B30: 4441033 | C30: 43023.59 | D30: 43023.639 | E30: 43018.383 | F30: 193004 | I30: single | J30: 69.833333
A31: 564082971 | B31: 3090259 | C31: 42509.502 | D31: 42509.563 | F31: 25849 | G31: success | H31: 42509.562 | I31: single | J31: 87.416667
A32: 60655363 | B32: 3212863 | C32: 42585.886 | D32: 42585.949 | F32: 67856 | G32: success | H32: 42585.946 | I32: single | J32: 91.033333
A33: 148765721 | B33: 3359784 | C33: 42674.405 | D33: 42674.431 | F33: 96432 | G33: success | H33: 42674.42 | I33: single | J33: 37.25
A34: 8787726 | B34: 3442252 | C34: 42714.783 | D34: 42714.837 | F34: 58745 | G34: failed_by_student | H34: 42714.529 | I34: single | J34: 77.1
A35: 355869457 | B35: 3512712 | C35: 42744.8 | D35: 42744.841 | F35: 142140 | G35: success | H35: 42744.849 | I35: single | J35: 59.15
A36: 354313060 | B36: 3526322 | C36: 42752.845 | D36: 42752.95 | F36: 24333 | G36: success | H36: 42752.921 | I36: single | J36: 151.91667
A37: 527459900 | B37: 3602433 | C37: 42781.924 | D37: 42781.952 | F37: 72684 | G37: success | H37: 42781.96 | I37: single | J37: 39.916667
A38: 848130149 | B38: 3830803 | C38: 42858.498 | D38: 42858.509 | F38: 82975 | G38: success | H38: 42858.456 | I38: single | J38: 14.983333
A39: 117173613 | B39: 3915243 | C39: 42877.364 | D39: 42877.365 | F39: 322426 | G39: success | H39: 42877.352 | I39: single | J39: 0.78333334
A40: 381283784 | B40: 4082049 | C40: 42917.341 | D40: 42917.402 | F40: 52049 | G40: canceled_by_student | H40: 42918.452 | I40: single | J40: 86.85
...

Sheet Учителя
A1: ID Teacher | B1: Age | C1: City | D1: Country | E1: Department | F1: Max Teaching Level | G1: Max Teaching Level ID | H1: Language Group
A2: 63364 | D2: Россия | F2: Advanced | G2: 6 | H2: rus
A3: 138650 | B3: 34 | C3: Херсон | D3: Украина | E3: School | F3: Pre-intermediate | G3: 3 | H3: rus
A4: 25990 | D4: Россия | F4: Upper-intermediate | G4: 5 | H4: rus
A5: 52373 | B5: 35 | C5: Магнитогорск | D5: Россия | E5: School | F5: Intermediate | G5: 4 | H5: rus
A6: 122778 | D6: Россия | F6: Advanced | G6: 6 | H6: rus
A7: 187138 | B7: 34 | C7: Полтава | D7: Украина | E7: School | F7: Advanced | G7: 6 | H7: rus
A8: 345359 | B8: 39 | C8: Санкт-Петербург | D8: Россия | E8: School | F8: Upper-intermediate | G8: 5 | H8: rus
A9: 62526 | B9: 37 | C9: Псков | D9: Россия | E9: School | F9: Advanced | G9: 6 | H9: rus
A10: 71226 | C10: Москва | D10: Россия | F10: Advanced | G10: 6 | H10: rus
A11: 24628 | B11: 37 | C11: Львов | D11: Украина | E11: School | F11: Intermediate | G11: 4 | H11: rus
A12: 46145 | D12: Россия | F12: Advanced | G12: 6 | H12: rus
A13: 58745 | B13: 27 | C13: Ногинск | D13: Россия | E13: School | F13: Advanced | G13: 6 | H13: rus
A14: 98044 | D14: Россия | F14: Advanced | G14: 6 | H14: rus
A15: 118693 | D15: Россия | F15: Advanced | G15: 6 | H15: rus
A16: 26745 | D16: Украина | F16: Pre-intermediate | G16: 3 | H16: rus
A17: 44845 | B17: 34 | C17: Винница | D17: Украина | E17: School | F17: Pre-intermediate | G17: 3 | H17: rus
A18: 52783 | B18: 31 | C18: Москва | D18: Россия | E18: School | F18: Intermediate | G18: 4 | H18: rus
A19: 198903 | B19: 30 | C19: Алматы | D19: Казахстан | E19: School | F19: Intermediate | G19: 4 | H19: rus
A20: 51916 | B20: 31 | C20: Ростов-на-Дону | D20: Россия | E20: School | F20: Advanced | G20: 6 | H20: rus
A21: 74491 | B21: 32 | C21: Челябинск | D21: Россия | E21: School | F21: Intermediate | G21: 4 | H21: rus
A22: 52017 | B22: 31 | C22: Бровары | D22: Украина | E22: School | F22: Upper-intermediate | G22: 5 | H22: rus
A23: 29916 | D23: Россия | F23: Advanced | G23: 6 | H23: rus
A24: 72103 | C24: Москва | D24: Россия | F24: Advanced | G24: 6 | H24: rus
A25: 72690 | B25: 30 | C25: Воронеж | D25: Россия | E25: School | F25: Upper-intermediate | G25: 5 | H25: rus
A26: 334121 | B26: 28 | C26: Köln | D26: Германия | E26: School | F26: Intermediate | G26: 4 | H26: rus
A27: 151440 | B27: 40 | C27: Петрозаводск | D27: Россия | E27: School | F27: Intermediate | G27: 4 | H27: rus
A28: 193004 | B28: 41 | C28: Харьков | D28: Украина | E28: School | F28: Intermediate | G28: 4 | H28: rus
A29: 16064 | B29: 31 | C29: Manila | D29: Филиппины | E29: School | F29: Advanced | G29: 6 | H29: eng
A30: 45890 | B30: 52 | D30: Великобритания | E30: School | F30: Advanced | G30: 6 | H30: eng
A31: 69146 | C31: Москва | D31: Россия | F31: Advanced | G31: 6 | H31: rus
A32: 84623 | B32: 37 | C32: Томск | D32: Россия | E32: School | F32: Pre-intermediate | G32: 3 | H32: rus
A33: 153811 | D33: Россия | F33: Advanced | G33: 6 | H33: rus
A34: 49340 | B34: 38 | C34: Лосино-Петровский | D34: Россия | E34: School | F34: Upper-intermediate | G34: 5 | H34: rus
A35: 51564 | B35: 29 | D35: Россия | E35: School | F35: Upper-intermediate | G35: 5 | H35: rus
A36: 121144 | B36: 38 | C36: Сыктывкар | D36: Россия | E36: School | F36: Intermediate | G36: 4 | H36: rus
A37: 136034 | D37: Россия | F37: Advanced | G37: 6 | H37: rus
A38: 49628 | D38: Россия | F38: Advanced | G38: 6 | H38: rus
A39: 50556 | F39: Advanced | G39: 6 | H39: rus
A40: 54349 | B40: 32 | C40: Санкт-Петербург | D40: Россия | E40: School | F40: Advanced | G40: 6 | H40: rus
...

Sheet Триальные уроки
A1: User ID | B1: ID Class | C1: Class Start Date Time | D1: Class End Date Time | E1: Class Removed Date Time | F1: ID Teacher | G1: Class Status | H1: Class Status Date Time | I1: Class Type | J1: Class Duration
A2: 325348 | B2: 3036485 | C2: 42465.444 | D2: 42465.427 | F2: 47743 | G2: success | H2: 42465.555 | I2: regular | J2: -24.683333
A3: 250209585 | B3: 3042917 | C3: 42469.608 | D3: 42469.619 | F3: 51564 | G3: success | H3: 42469.625 | I3: regular | J3: 15.433333
A4: 518406438 | B4: 3074966 | C4: 42491.763 | D4: 42491.825 | F4: 26896 | G4: failed_by_student | H4: 42491.514 | I4: regular | J4: 89.3
A5: 666791637 | B5: 3103245 | C5: 42511.422 | D5: 42511.483 | F5: 51450 | G5: canceled_by_student | H5: 42512.234 | I5: regular | J5: 88.7
A6: 310771064 | B6: 3123907 | C6: 42525.455 | D6: 42525.454 | F6: 19513 | G6: success | H6: 42525.478 | I6: regular | J6: -1.05
A7: 820726831 | B7: 3137396 | C7: 42534.825 | D7: 42534.837 | F7: 45226 | G7: success | H7: 42535.341 | I7: regular | J7: 16.283333
A8: 87910119 | B8: 3142195 | C8: 42537.296 | D8: 42537.36 | F8: 46409 | G8: canceled_by_student | H8: 42537.587 | I8: regular | J8: 90.983333
A9: 557318231 | B9: 3163558 | C9: 42551.623 | D9: 42551.612 | F9: 16064 | G9: success | H9: 42551.796 | I9: regular | J9: -16.1
A10: 378031781 | B10: 3165081 | C10: 42552.925 | D10: 42552.95 | E10: 42552.671 | F10: 54349 | I10: regular | J10: 36.916667
A11: 819834854 | B11: 3179696 | C11: 42562.914 | D11: 42562.938 | F11: 62525 | G11: canceled_by_teacher | H11: 42562.979 | I11: regular | J11: 34.55
A12: 53930100 | B12: 3190831 | C12: 42570.739 | D12: 42570.757 | F12: 46401 | G12: success | H12: 42571.807 | I12: regular | J12: 27.05
A13: 577136653 | B13: 3393876 | C13: 42706.742 | D13: 42706.765 | F13: 73877 | G13: canceled_by_student | H13: 42707.632 | I13: single | J13: 33.466667
A14: 820269817 | B14: 3491015 | C14: 42733.853 | D14: 42733.831 | F14: 129840 | G14: failed_by_student | H14: 42733.931 | I14: single | J14: -31.833333
A15: 812848522 | B15: 3517332 | C15: 42748.424 | D15: 42748.463 | F15: 22703 | G15: canceled_by_student | H15: 42748.647 | I15: single | J15: 56.6
A16: 702993006 | B16: 3702595 | C16: 42823.712 | D16: 42823.786 | F16: 62526 | G16: success | H16: 42823.829 | I16: single | J16: 107.06667
A17: 275505680 | B17: 4493327 | C17: 43015.955 | D17: 43015.972 | F17: 26745 | G17: success | H17: 43016.42 | I17: single | J17: 23.716667
A18: 265631576 | B18: 3017789 | C18: 42452.562 | D18: 42452.577 | F18: 51907 | G18: canceled_by_teacher | H18: 42452.584 | I18: single | J18: 22.4
A19: 312890749 | B19: 3051957 | C19: 42478.436 | D19: 42478.457 | F19: 52940 | G19: success | H19: 42478.425 | I19: single | J19: 31.283333
A20: 812848522 | B20: 3459655 | C20: 42723.499 | D20: 42723.504 | F20: 22703 | G20: success | H20: 42723.543 | I20: single | J20: 7.2333333
A21: 825271993 | B21: 3481219 | C21: 42731.801 | D21: 42731.854 | F21: 37836 | G21: success | H21: 42731.832 | I21: single | J21: 75.516667
A22: 735566020 | B22: 3641656 | C22: 42824.847 | D22: 42824.922 | E22: 42810.555 | F22: 52344 | I22: single | J22: 108.6
A23: 459374225 | B23: 3744356 | C23: 42829.91 | D23: 42829.922 | F23: 74354 | G23: success | H23: 42829.957 | I23: single | J23: 17.45
A24: 750711381 | B24: 3770985 | C24: 42836.586 | D24: 42836.605 | F24: 155465 | G24: failed_by_student | H24: 42836.644 | I24: single | J24: 26.95
A25: 354074093 | B25: 4183165 | C25: 42944.828 | D25: 42944.821 | F25: 44903 | G25: success | H25: 42944.854 | I25: single | J25: -8.7333333
A26: 312890749 | B26: 4234049 | C26: 42958.425 | D26: 42958.457 | F26: 52940 | G26: success | H26: 42958.447 | I26: single | J26: 45.183333
A27: 363117914 | B27: 4240904 | C27: 42958.835 | D27: 42958.872 | F27: 121144 | G27: success | H27: 42958.921 | I27: single | J27: 54
A28: 460717125 | B28: 4279632 | C28: 42967.474 | D28: 42967.466 | F28: 138716 | G28: canceled_by_teacher | H28: 42968.441 | I28: single | J28: -10.7
A29: 646897024 | B29: 4394006 | C29: 42994.387 | D29: 42994.463 | E29: 42995.859 | F29: 15605 | G29: moved | H29: 42995.916 | I29: single | J29: 110.01667
A30: 601916433 | B30: 4441033 | C30: 43023.59 | D30: 43023.639 | E30: 43018.383 | F30: 193004 | I30: single | J30: 69.833333
A31: 564082971 | B31: 3090259 | C31: 42509.502 | D31: 42509.563 | F31: 25849 | G31: success | H31: 42509.562 | I31: single | J31: 87.416667
A32: 60655363 | B32: 3212863 | C32: 42585.886 | D32: 42585.949 | F32: 67856 | G32: success | H32: 42585.946 | I32: single | J32: 91.033333
A33: 148765721 | B33: 3359784 | C33: 42674.405 | D33: 42674.431 | F33: 96432 | G33: success | H33: 42674.42 | I33: single | J33: 37.25
A34: 8787726 | B34: 3442252 | C34: 42714.783 | D34: 42714.837 | F34: 58745 | G34: failed_by_student | H34: 42714.529 | I34: single | J34: 77.1
A35: 355869457 | B35: 3512712 | C35: 42744.8 | D35: 42744.841 | F35: 142140 | G35: success | H35: 42744.849 | I35: single | J35: 59.15
A36: 354313060 | B36: 3526322 | C36: 42752.845 | D36: 42752.95 | F36: 24333 | G36: success | H36: 42752.921 | I36: single | J36: 151.91667
A37: 527459900 | B37: 3602433 | C37: 42781.924 | D37: 42781.952 | F37: 72684 | G37: success | H37: 42781.96 | I37: single | J37: 39.916667
A38: 848130149 | B38: 3830803 | C38: 42858.498 | D38: 42858.509 | F38: 82975 | G38: success | H38: 42858.456 | I38: single | J38: 14.983333
A39: 117173613 | B39: 3915243 | C39: 42877.364 | D39: 42877.365 | F39: 322426 | G39: success | H39: 42877.352 | I39: single | J39: 0.78333334
A40: 381283784 | B40: 4082049 | C40: 42917.341 | D40: 42917.402 | F40: 52049 | G40: canceled_by_student | H40: 42918.452 | I40: single | J40: 86.85
...

Sheet Успешные уроки МСК и СПБ
A1: User ID | B1: ID Class | C1: Class Start Date Time | D1: Class End Date Time | E1: Class Removed Date Time | F1: ID Teacher | G1: City | H1: Class Status | I1: Class Status Date Time | J1: Class Type | K1: Class Duration
A2: 325348 | B2: 3036485 | C2: 42465.444 | D2: 42465.427 | F2: 47743 | G2: =VLOOKUP(F2,Учителя!$A:$H,3,0) -> Вологда | H2: success | I2: 42465.555 | J2: regular | K2: -24.683333
A3: 250209585 | B3: 3042917 | C3: 42469.608 | D3: 42469.619 | F3: 51564 | G3: =VLOOKUP(F3,Учителя!$A:$H,3,0) -> 0 | H3: success | I3: 42469.625 | J3: regular | K3: 15.433333
A4: 518406438 | B4: 3074966 | C4: 42491.763 | D4: 42491.825 | F4: 26896 | G4: =VLOOKUP(F4,Учителя!$A:$H,3,0) -> Северодонецк | H4: failed_by_student | I4: 42491.514 | J4: regular | K4: 89.3
A5: 666791637 | B5: 3103245 | C5: 42511.422 | D5: 42511.483 | F5: 51450 | G5: =VLOOKUP(F5,Учителя!$A:$H,3,0) -> Новосибирск | H5: canceled_by_student | I5: 42512.234 | J5: regular | K5: 88.7
A6: 310771064 | B6: 3123907 | C6: 42525.455 | D6: 42525.454 | F6: 19513 | G6: =VLOOKUP(F6,Учителя!$A:$H,3,0) -> 0 | H6: success | I6: 42525.478 | J6: regular | K6: -1.05
A7: 820726831 | B7: 3137396 | C7: 42534.825 | D7: 42534.837 | F7: 45226 | G7: =VLOOKUP(F7,Учителя!$A:$H,3,0) -> Нижний Новгород | H7: success | I7: 42535.341 | J7: regular | K7: 16.283333
A8: 87910119 | B8: 3142195 | C8: 42537.296 | D8: 42537.36 | F8: 46409 | G8: =VLOOKUP(F8,Учителя!$A:$H,3,0) -> 0 | H8: canceled_by_student | I8: 42537.587 | J8: regular | K8: 90.983333
A9: 557318231 | B9: 3163558 | C9: 42551.623 | D9: 42551.612 | F9: 16064 | G9: =VLOOKUP(F9,Учителя!$A:$H,3,0) -> Manila | H9: success | I9: 42551.796 | J9: regular | K9: -16.1
A10: 378031781 | B10: 3165081 | C10: 42552.925 | D10: 42552.95 | E10: 42552.671 | F10: 54349 | G10: =VLOOKUP(F10,Учителя!$A:$H,3,0) -> Санкт-Петербург | J10: regular | K10: 36.916667
A11: 819834854 | B11: 3179696 | C11: 42562.914 | D11: 42562.938 | F11: 62525 | G11: =VLOOKUP(F11,Учителя!$A:$H,3,0) -> Краснодар | H11: canceled_by_teacher | I11: 42562.979 | J11: regular | K11: 34.55
A12: 53930100 | B12: 3190831 | C12: 42570.739 | D12: 42570.757 | F12: 46401 | G12: =VLOOKUP(F12,Учителя!$A:$H,3,0) -> Москва | H12: success | I12: 42571.807 | J12: regular | K12: 27.05
A13: 577136653 | B13: 3393876 | C13: 42706.742 | D13: 42706.765 | F13: 73877 | G13: =VLOOKUP(F13,Учителя!$A:$H,3,0) -> Москва | H13: canceled_by_student | I13: 42707.632 | J13: single | K13: 33.466667
A14: 820269817 | B14: 3491015 | C14: 42733.853 | D14: 42733.831 | F14: 129840 | G14: =VLOOKUP(F14,Учителя!$A:$H,3,0) -> Смоленск | H14: failed_by_student | I14: 42733.931 | J14: single | K14: -31.833333
A15: 812848522 | B15: 3517332 | C15: 42748.424 | D15: 42748.463 | F15: 22703 | G15: =VLOOKUP(F15,Учителя!$A:$H,3,0) -> Александров | H15: canceled_by_student | I15: 42748.647 | J15: single | K15: 56.6
A16: 702993006 | B16: 3702595 | C16: 42823.712 | D16: 42823.786 | F16: 62526 | G16: =VLOOKUP(F16,Учителя!$A:$H,3,0) -> Псков | H16: success | I16: 42823.829 | J16: single | K16: 107.06667
A17: 275505680 | B17: 4493327 | C17: 43015.955 | D17: 43015.972 | F17: 26745 | G17: =VLOOKUP(F17,Учителя!$A:$H,3,0) -> 0 | H17: success | I17: 43016.42 | J17: single | K17: 23.716667
A18: 265631576 | B18: 3017789 | C18: 42452.562 | D18: 42452.577 | F18: 51907 | G18: =VLOOKUP(F18,Учителя!$A:$H,3,0) -> Москва | H18: canceled_by_teacher | I18: 42452.584 | J18: single | K18: 22.4
A19: 312890749 | B19: 3051957 | C19: 42478.436 | D19: 42478.457 | F19: 52940 | G19: =VLOOKUP(F19,Учителя!$A:$H,3,0) -> Барнаул | H19: success | I19: 42478.425 | J19: single | K19: 31.283333
A20: 812848522 | B20: 3459655 | C20: 42723.499 | D20: 42723.504 | F20: 22703 | G20: =VLOOKUP(F20,Учителя!$A:$H,3,0) -> Александров | H20: success | I20: 42723.543 | J20: single | K20: 7.2333333
A21: 825271993 | B21: 3481219 | C21: 42731.801 | D21: 42731.854 | F21: 37836 | G21: =VLOOKUP(F21,Учителя!$A:$H,3,0) -> Киев | H21: success | I21: 42731.832 | J21: single | K21: 75.516667
A22: 735566020 | B22: 3641656 | C22: 42824.847 | D22: 42824.922 | E22: 42810.555 | F22: 52344 | G22: =VLOOKUP(F22,Учителя!$A:$H,3,0) -> Уфа | J22: single | K22: 108.6
A23: 459374225 | B23: 3744356 | C23: 42829.91 | D23: 42829.922 | F23: 74354 | G23: =VLOOKUP(F23,Учителя!$A:$H,3,0) -> Казань | H23: success | I23: 42829.957 | J23: single | K23: 17.45
A24: 750711381 | B24: 3770985 | C24: 42836.586 | D24: 42836.605 | F24: 155465 | G24: =VLOOKUP(F24,Учителя!$A:$H,3,0) -> Санкт-Петербург | H24: failed_by_student | I24: 42836.644 | J24: single | K24: 26.95
A25: 354074093 | B25: 4183165 | C25: 42944.828 | D25: 42944.821 | F25: 44903 | G25: =VLOOKUP(F25,Учителя!$A:$H,3,0) -> Киев | H25: success | I25: 42944.854 | J25: single | K25: -8.7333333
A26: 312890749 | B26: 4234049 | C26: 42958.425 | D26: 42958.457 | F26: 52940 | G26: =VLOOKUP(F26,Учителя!$A:$H,3,0) -> Барнаул | H26: success | I26: 42958.447 | J26: single | K26: 45.183333
A27: 363117914 | B27: 4240904 | C27: 42958.835 | D27: 42958.872 | F27: 121144 | G27: =VLOOKUP(F27,Учителя!$A:$H,3,0) -> Сыктывкар | H27: success | I27: 42958.921 | J27: single | K27: 54
A28: 460717125 | B28: 4279632 | C28: 42967.474 | D28: 42967.466 | F28: 138716 | G28: =VLOOKUP(F28,Учителя!$A:$H,3,0) -> Харьков | H28: canceled_by_teacher | I28: 42968.441 | J28: single | K28: -10.7
A29: 646897024 | B29: 4394006 | C29: 42994.387 | D29: 42994.463 | E29: 42995.859 | F29: 15605 | G29: =VLOOKUP(F29,Учителя!$A:$H,3,0) -> Белгород-Днестровский | H29: moved | I29: 42995.916 | J29: single | K29: 110.01667
A30: 601916433 | B30: 4441033 | C30: 43023.59 | D30: 43023.639 | E30: 43018.383 | F30: 193004 | G30: =VLOOKUP(F30,Учителя!$A:$H,3,0) -> Харьков | J30: single | K30: 69.833333
A31: 564082971 | B31: 3090259 | C31: 42509.502 | D31: 42509.563 | F31: 25849 | G31: =VLOOKUP(F31,Учителя!$A:$H,3,0) -> Пермь | H31: success | I31: 42509.562 | J31: single | K31: 87.416667
A32: 60655363 | B32: 3212863 | C32: 42585.886 | D32: 42585.949 | F32: 67856 | G32: =VLOOKUP(F32,Учителя!$A:$H,3,0) -> Калининград | H32: success | I32: 42585.946 | J32: single | K32: 91.033333
A33: 148765721 | B33: 3359784 | C33: 42674.405 | D33: 42674.431 | F33: 96432 | G33: =VLOOKUP(F33,Учителя!$A:$H,3,0) -> Ростов-на-Дону | H33: success | I33: 42674.42 | J33: single | K33: 37.25
A34: 8787726 | B34: 3442252 | C34: 42714.783 | D34: 42714.837 | F34: 58745 | G34: =VLOOKUP(F34,Учителя!$A:$H,3,0) -> Ногинск | H34: failed_by_student | I34: 42714.529 | J34: single | K34: 77.1
A35: 355869457 | B35: 3512712 | C35: 42744.8 | D35: 42744.841 | F35: 142140 | G35: =VLOOKUP(F35,Учителя!$A:$H,3,0) -> Екатеринбург | H35: success | I35: 42744.849 | J35: single | K35: 59.15
A36: 354313060 | B36: 3526322 | C36: 42752.845 | D36: 42752.95 | F36: 24333 | G36: =VLOOKUP(F36,Учителя!$A:$H,3,0) -> Житомир | H36: success | I36: 42752.921 | J36: single | K36: 151.91667
A37: 527459900 | B37: 3602433 | C37: 42781.924 | D37: 42781.952 | F37: 72684 | G37: =VLOOKUP(F37,Учителя!$A:$H,3,0) -> Симферополь | H37: success | I37: 42781.96 | J37: single | K37: 39.916667
A38: 848130149 | B38: 3830803 | C38: 42858.498 | D38: 42858.509 | F38: 82975 | G38: =VLOOKUP(F38,Учителя!$A:$H,3,0) -> Иваново | H38: success | I38: 42858.456 | J38: single | K38: 14.983333
A39: 117173613 | B39: 3915243 | C39: 42877.364 | D39: 42877.365 | F39: 322426 | G39: =VLOOKUP(F39,Учителя!$A:$H,3,0) -> Черкассы | H39: success | I39: 42877.352 | J39: single | K39: 0.78333334
A40: 381283784 | B40: 4082049 | C40: 42917.341 | D40: 42917.402 | F40: 52049 | G40: =VLOOKUP(F40,Учителя!$A:$H,3,0) -> Челябинск | H40: canceled_by_student | I40: 42918.452 | J40: single | K40: 86.85
...

Sheet Успешные уроки 68110
A1: User ID | B1: ID Class | C1: Class Start Date Time | D1: Class End Date Time | E1: Class Removed Date Time | F1: ID Teacher | G1: Class Status | H1: Class Status Date Time | I1: Class Type | J1: Class Duration
A2: 325348 | B2: 3036485 | C2: 42465.444 | D2: 42465.427 | F2: 47743 | G2: success | H2: 42465.555 | I2: regular | J2: -24.683333
A3: 250209585 | B3: 3042917 | C3: 42469.608 | D3: 42469.619 | F3: 51564 | G3: success | H3: 42469.625 | I3: regular | J3: 15.433333
A4: 518406438 | B4: 3074966 | C4: 42491.763 | D4: 42491.825 | F4: 26896 | G4: failed_by_student | H4: 42491.514 | I4: regular | J4: 89.3
A5: 666791637 | B5: 3103245 | C5: 42511.422 | D5: 42511.483 | F5: 51450 | G5: canceled_by_student | H5: 42512.234 | I5: regular | J5: 88.7
A6: 310771064 | B6: 3123907 | C6: 42525.455 | D6: 42525.454 | F6: 19513 | G6: success | H6: 42525.478 | I6: regular | J6: -1.05
A7: 820726831 | B7: 3137396 | C7: 42534.825 | D7: 42534.837 | F7: 45226 | G7: success | H7: 42535.341 | I7: regular | J7: 16.283333
A8: 87910119 | B8: 3142195 | C8: 42537.296 | D8: 42537.36 | F8: 46409 | G8: canceled_by_student | H8: 42537.587 | I8: regular | J8: 90.983333
A9: 557318231 | B9: 3163558 | C9: 42551.623 | D9: 42551.612 | F9: 16064 | G9: success | H9: 42551.796 | I9: regular | J9: -16.1
A10: 378031781 | B10: 3165081 | C10: 42552.925 | D10: 42552.95 | E10: 42552.671 | F10: 54349 | I10: regular | J10: 36.916667
A11: 819834854 | B11: 3179696 | C11: 42562.914 | D11: 42562.938 | F11: 62525 | G11: canceled_by_teacher | H11: 42562.979 | I11: regular | J11: 34.55
A12: 53930100 | B12: 3190831 | C12: 42570.739 | D12: 42570.757 | F12: 46401 | G12: success | H12: 42571.807 | I12: regular | J12: 27.05
A13: 577136653 | B13: 3393876 | C13: 42706.742 | D13: 42706.765 | F13: 73877 | G13: canceled_by_student | H13: 42707.632 | I13: single | J13: 33.466667
A14: 820269817 | B14: 3491015 | C14: 42733.853 | D14: 42733.831 | F14: 129840 | G14: failed_by_student | H14: 42733.931 | I14: single | J14: -31.833333
A15: 812848522 | B15: 3517332 | C15: 42748.424 | D15: 42748.463 | F15: 22703 | G15: canceled_by_student | H15: 42748.647 | I15: single | J15: 56.6
A16: 702993006 | B16: 3702595 | C16: 42823.712 | D16: 42823.786 | F16: 62526 | G16: success | H16: 42823.829 | I16: single | J16: 107.06667
A17: 275505680 | B17: 4493327 | C17: 43015.955 | D17: 43015.972 | F17: 26745 | G17: success | H17: 43016.42 | I17: single | J17: 23.716667
A18: 265631576 | B18: 3017789 | C18: 42452.562 | D18: 42452.577 | F18: 51907 | G18: canceled_by_teacher | H18: 42452.584 | I18: single | J18: 22.4
A19: 312890749 | B19: 3051957 | C19: 42478.436 | D19: 42478.457 | F19: 52940 | G19: success | H19: 42478.425 | I19: single | J19: 31.283333
A20: 812848522 | B20: 3459655 | C20: 42723.499 | D20: 42723.504 | F20: 22703 | G20: success | H20: 42723.543 | I20: single | J20: 7.2333333
A21: 825271993 | B21: 3481219 | C21: 42731.801 | D21: 42731.854 | F21: 37836 | G21: success | H21: 42731.832 | I21: single | J21: 75.516667
A22: 735566020 | B22: 3641656 | C22: 42824.847 | D22: 42824.922 | E22: 42810.555 | F22: 52344 | I22: single | J22: 108.6
A23: 459374225 | B23: 3744356 | C23: 42829.91 | D23: 42829.922 | F23: 74354 | G23: success | H23: 42829.957 | I23: single | J23: 17.45
A24: 750711381 | B24: 3770985 | C24: 42836.586 | D24: 42836.605 | F24: 155465 | G24: failed_by_student | H24: 42836.644 | I24: single | J24: 26.95
A25: 354074093 | B25: 4183165 | C25: 42944.828 | D25: 42944.821 | F25: 44903 | G25: success | H25: 42944.854 | I25: single | J25: -8.7333333
A26: 312890749 | B26: 4234049 | C26: 42958.425 | D26: 42958.457 | F26: 52940 | G26: success | H26: 42958.447 | I26: single | J26: 45.183333
A27: 363117914 | B27: 4240904 | C27: 42958.835 | D27: 42958.872 | F27: 121144 | G27: success | H27: 42958.921 | I27: single | J27: 54
A28: 460717125 | B28: 4279632 | C28: 42967.474 | D28: 42967.466 | F28: 138716 | G28: canceled_by_teacher | H28: 42968.441 | I28: single | J28: -10.7
A29: 646897024 | B29: 4394006 | C29: 42994.387 | D29: 42994.463 | E29: 42995.859 | F29: 15605 | G29: moved | H29: 42995.916 | I29: single | J29: 110.01667
A30: 601916433 | B30: 4441033 | C30: 43023.59 | D30: 43023.639 | E30: 43018.383 | F30: 193004 | I30: single | J30: 69.833333
A31: 564082971 | B31: 3090259 | C31: 42509.502 | D31: 42509.563 | F31: 25849 | G31: success | H31: 42509.562 | I31: single | J31: 87.416667
A32: 60655363 | B32: 3212863 | C32: 42585.886 | D32: 42585.949 | F32: 67856 | G32: success | H32: 42585.946 | I32: single | J32: 91.033333
A33: 148765721 | B33: 3359784 | C33: 42674.405 | D33: 42674.431 | F33: 96432 | G33: success | H33: 42674.42 | I33: single | J33: 37.25
A34: 8787726 | B34: 3442252 | C34: 42714.783 | D34: 42714.837 | F34: 58745 | G34: failed_by_student | H34: 42714.529 | I34: single | J34: 77.1
A35: 355869457 | B35: 3512712 | C35: 42744.8 | D35: 42744.841 | F35: 142140 | G35: success | H35: 42744.849 | I35: single | J35: 59.15
A36: 354313060 | B36: 3526322 | C36: 42752.845 | D36: 42752.95 | F36: 24333 | G36: success | H36: 42752.921 | I36: single | J36: 151.91667
A37: 527459900 | B37: 3602433 | C37: 42781.924 | D37: 42781.952 | F37: 72684 | G37: success | H37: 42781.96 | I37: single | J37: 39.916667
A38: 848130149 | B38: 3830803 | C38: 42858.498 | D38: 42858.509 | F38: 82975 | G38: success | H38: 42858.456 | I38: single | J38: 14.983333
A39: 117173613 | B39: 3915243 | C39: 42877.364 | D39: 42877.365 | F39: 322426 | G39: success | H39: 42877.352 | I39: single | J39: 0.78333334
A40: 381283784 | B40: 4082049 | C40: 42917.341 | D40: 42917.402 | F40: 52049 | G40: canceled_by_student | H40: 42918.452 | I40: single | J40: 86.85
...

Sheet Подозрительные уроки
A1: User ID | B1: ID Class | C1: Class Start Date Time | D1: Class End Date Time | E1: Class Removed Date Time | F1: ID Teacher | G1: Class Status | H1: Class Status Date Time | I1: Class Type | J1: Class Duration | K1: Подозрительный урок
A2: 325348 | B2: 3036485 | C2: 42465.444 | D2: 42465.427 | F2: 47743 | G2: success | H2: 42465.555 | I2: regular | J2: -24.683333 | K2: =OR(IF(J2<30,1,0),IF(J2>120,1,0)) -> TRUE
A3: 250209585 | B3: 3042917 | C3: 42469.608 | D3: 42469.619 | F3: 51564 | G3: success | H3: 42469.625 | I3: regular | J3: 15.433333 | K3: =OR(IF(J3<30,1,0),IF(J3>120,1,0)) -> TRUE
A4: 518406438 | B4: 3074966 | C4: 42491.763 | D4: 42491.825 | F4: 26896 | G4: failed_by_student | H4: 42491.514 | I4: regular | J4: 89.3 | K4: =OR(IF(J4<30,1,0),IF(J4>120,1,0)) -> FALSE
A5: 666791637 | B5: 3103245 | C5: 42511.422 | D5: 42511.483 | F5: 51450 | G5: canceled_by_student | H5: 42512.234 | I5: regular | J5: 88.7 | K5: =OR(IF(J5<30,1,0),IF(J5>120,1,0)) -> FALSE
A6: 310771064 | B6: 3123907 | C6: 42525.455 | D6: 42525.454 | F6: 19513 | G6: success | H6: 42525.478 | I6: regular | J6: -1.05 | K6: =OR(IF(J6<30,1,0),IF(J6>120,1,0)) -> TRUE
A7: 820726831 | B7: 3137396 | C7: 42534.825 | D7: 42534.837 | F7: 45226 | G7: success | H7: 42535.341 | I7: regular | J7: 16.283333 | K7: =OR(IF(J7<30,1,0),IF(J7>120,1,0)) -> TRUE
A8: 87910119 | B8: 3142195 | C8: 42537.296 | D8: 42537.36 | F8: 46409 | G8: canceled_by_student | H8: 42537.587 | I8: regular | J8: 90.983333 | K8: =OR(IF(J8<30,1,0),IF(J8>120,1,0)) -> FALSE
A9: 557318231 | B9: 3163558 | C9: 42551.623 | D9: 42551.612 | F9: 16064 | G9: success | H9: 42551.796 | I9: regular | J9: -16.1 | K9: =OR(IF(J9<30,1,0),IF(J9>120,1,0)) -> TRUE
A10: 378031781 | B10: 3165081 | C10: 42552.925 | D10: 42552.95 | E10: 42552.671 | F10: 54349 | I10: regular | J10: 36.916667 | K10: =OR(IF(J10<30,1,0),IF(J10>120,1,0)) -> FALSE
A11: 819834854 | B11: 3179696 | C11: 42562.914 | D11: 42562.938 | F11: 62525 | G11: canceled_by_teacher | H11: 42562.979 | I11: regular | J11: 34.55 | K11: =OR(IF(J11<30,1,0),IF(J11>120,1,0)) -> FALSE
A12: 53930100 | B12: 3190831 | C12: 42570.739 | D12: 42570.757 | F12: 46401 | G12: success | H12: 42571.807 | I12: regular | J12: 27.05 | K12: =OR(IF(J12<30,1,0),IF(J12>120,1,0)) -> TRUE
A13: 577136653 | B13: 3393876 | C13: 42706.742 | D13: 42706.765 | F13: 73877 | G13: canceled_by_student | H13: 42707.632 | I13: single | J13: 33.466667 | K13: =OR(IF(J13<30,1,0),IF(J13>120,1,0)) -> FALSE
A14: 820269817 | B14: 3491015 | C14: 42733.853 | D14: 42733.831 | F14: 129840 | G14: failed_by_student | H14: 42733.931 | I14: single | J14: -31.833333 | K14: =OR(IF(J14<30,1,0),IF(J14>120,1,0)) -> TRUE
A15: 812848522 | B15: 3517332 | C15: 42748.424 | D15: 42748.463 | F15: 22703 | G15: canceled_by_student | H15: 42748.647 | I15: single | J15: 56.6 | K15: =OR(IF(J15<30,1,0),IF(J15>120,1,0)) -> FALSE
A16: 702993006 | B16: 3702595 | C16: 42823.712 | D16: 42823.786 | F16: 62526 | G16: success | H16: 42823.829 | I16: single | J16: 107.06667 | K16: =OR(IF(J16<30,1,0),IF(J16>120,1,0)) -> FALSE
A17: 275505680 | B17: 4493327 | C17: 43015.955 | D17: 43015.972 | F17: 26745 | G17: success | H17: 43016.42 | I17: single | J17: 23.716667 | K17: =OR(IF(J17<30,1,0),IF(J17>120,1,0)) -> TRUE
A18: 265631576 | B18: 3017789 | C18: 42452.562 | D18: 42452.577 | F18: 51907 | G18: canceled_by_teacher | H18: 42452.584 | I18: single | J18: 22.4 | K18: =OR(IF(J18<30,1,0),IF(J18>120,1,0)) -> TRUE
A19: 312890749 | B19: 3051957 | C19: 42478.436 | D19: 42478.457 | F19: 52940 | G19: success | H19: 42478.425 | I19: single | J19: 31.283333 | K19: =OR(IF(J19<30,1,0),IF(J19>120,1,0)) -> FALSE
A20: 812848522 | B20: 3459655 | C20: 42723.499 | D20: 42723.504 | F20: 22703 | G20: success | H20: 42723.543 | I20: single | J20: 7.2333333 | K20: =OR(IF(J20<30,1,0),IF(J20>120,1,0)) -> TRUE
A21: 825271993 | B21: 3481219 | C21: 42731.801 | D21: 42731.854 | F21: 37836 | G21: success | H21: 42731.832 | I21: single | J21: 75.516667 | K21: =OR(IF(J21<30,1,0),IF(J21>120,1,0)) -> FALSE
A22: 735566020 | B22: 3641656 | C22: 42824.847 | D22: 42824.922 | E22: 42810.555 | F22: 52344 | I22: single | J22: 108.6 | K22: =OR(IF(J22<30,1,0),IF(J22>120,1,0)) -> FALSE
A23: 459374225 | B23: 3744356 | C23: 42829.91 | D23: 42829.922 | F23: 74354 | G23: success | H23: 42829.957 | I23: single | J23: 17.45 | K23: =OR(IF(J23<30,1,0),IF(J23>120,1,0)) -> TRUE
A24: 750711381 | B24: 3770985 | C24: 42836.586 | D24: 42836.605 | F24: 155465 | G24: failed_by_student | H24: 42836.644 | I24: single | J24: 26.95 | K24: =OR(IF(J24<30,1,0),IF(J24>120,1,0)) -> TRUE
A25: 354074093 | B25: 4183165 | C25: 42944.828 | D25: 42944.821 | F25: 44903 | G25: success | H25: 42944.854 | I25: single | J25: -8.7333333 | K25: =OR(IF(J25<30,1,0),IF(J25>120,1,0)) -> TRUE
A26: 312890749 | B26: 4234049 | C26: 42958.425 | D26: 42958.457 | F26: 52940 | G26: success | H26: 42958.447 | I26: single | J26: 45.183333 | K26: =OR(IF(J26<30,1,0),IF(J26>120,1,0)) -> FALSE
A27: 363117914 | B27: 4240904 | C27: 42958.835 | D27: 42958.872 | F27: 121144 | G27: success | H27: 42958.921 | I27: single | J27: 54 | K27: =OR(IF(J27<30,1,0),IF(J27>120,1,0)) -> FALSE
A28: 460717125 | B28: 4279632 | C28: 42967.474 | D28: 42967.466 | F28: 138716 | G28: canceled_by_teacher | H28: 42968.441 | I28: single | J28: -10.7 | K28: =OR(IF(J28<30,1,0),IF(J28>120,1,0)) -> TRUE
A29: 646897024 | B29: 4394006 | C29: 42994.387 | D29: 42994.463 | E29: 42995.859 | F29: 15605 | G29: moved | H29: 42995.916 | I29: single | J29: 110.01667 | K29: =OR(IF(J29<30,1,0),IF(J29>120,1,0)) -> FALSE
A30: 601916433 | B30: 4441033 | C30: 43023.59 | D30: 43023.639 | E30: 43018.383 | F30: 193004 | I30: single | J30: 69.833333 | K30: =OR(IF(J30<30,1,0),IF(J30>120,1,0)) -> FALSE
A31: 564082971 | B31: 3090259 | C31: 42509.502 | D31: 42509.563 | F31: 25849 | G31: success | H31: 42509.562 | I31: single | J31: 87.416667 | K31: =OR(IF(J31<30,1,0),IF(J31>120,1,0)) -> FALSE
A32: 60655363 | B32: 3212863 | C32: 42585.886 | D32: 42585.949 | F32: 67856 | G32: success | H32: 42585.946 | I32: single | J32: 91.033333 | K32: =OR(IF(J32<30,1,0),IF(J32>120,1,0)) -> FALSE
A33: 148765721 | B33: 3359784 | C33: 42674.405 | D33: 42674.431 | F33: 96432 | G33: success | H33: 42674.42 | I33: single | J33: 37.25 | K33: =OR(IF(J33<30,1,0),IF(J33>120,1,0)) -> FALSE
A34: 8787726 | B34: 3442252 | C34: 42714.783 | D34: 42714.837 | F34: 58745 | G34: failed_by_student | H34: 42714.529 | I34: single | J34: 77.1 | K34: =OR(IF(J34<30,1,0),IF(J34>120,1,0)) -> FALSE
A35: 355869457 | B35: 3512712 | C35: 42744.8 | D35: 42744.841 | F35: 142140 | G35: success | H35: 42744.849 | I35: single | J35: 59.15 | K35: =OR(IF(J35<30,1,0),IF(J35>120,1,0)) -> FALSE
A36: 354313060 | B36: 3526322 | C36: 42752.845 | D36: 42752.95 | F36: 24333 | G36: success | H36: 42752.921 | I36: single | J36: 151.91667 | K36: =OR(IF(J36<30,1,0),IF(J36>120,1,0)) -> TRUE
A37: 527459900 | B37: 3602433 | C37: 42781.924 | D37: 42781.952 | F37: 72684 | G37: success | H37: 42781.96 | I37: single | J37: 39.916667 | K37: =OR(IF(J37<30,1,0),IF(J37>120,1,0)) -> FALSE
A38: 848130149 | B38: 3830803 | C38: 42858.498 | D38: 42858.509 | F38: 82975 | G38: success | H38: 42858.456 | I38: single | J38: 14.983333 | K38: =OR(IF(J38<30,1,0),IF(J38>120,1,0)) -> TRUE
A39: 117173613 | B39: 3915243 | C39: 42877.364 | D39: 42877.365 | F39: 322426 | G39: success | H39: 42877.352 | I39: single | J39: 0.78333334 | K39: =OR(IF(J39<30,1,0),IF(J39>120,1,0)) -> TRUE
A40: 381283784 | B40: 4082049 | C40: 42917.341 | D40: 42917.402 | F40: 52049 | G40: canceled_by_student | H40: 42918.452 | I40: single | J40: 86.85 | K40: =OR(IF(J40<30,1,0),IF(J40>120,1,0)) -> FALSE
...
